Workbook

Sheet Bank Balance
A2: Bank Balance
A4: Row Labels | B4: Sum of Amount (USD)
A5: Jan | B5: 1955526.2
A6: Feb | B6: 947096.7
A7: Mar | B7: 987757.94
A8: Apr | B8: 793996.47
A9: May | B9: 663264.51
A10: Jun | B10: 735495.79
A11: Jul | B11: 735495.79
A12: Aug | B12: 735495.79
A13: Sep | B13: 735495.79
A14: Oct | B14: 735495.79
A15: Nov | B15: 735495.79
A16: Dec | B16: 735495.79
A17: Grand Total | B17: 10496112

Sheet Bank 
A1: Raw Data | J1: Overall
A2: Date | B2: Entity | C2: Bank Balance | D2: Currency | E2: Currency Amount | F2: Amount (USD) | H2: FOREX
A3: 46023 | B3: HQ | C3: East West | D3: USD | E3: ='AXT -Eastwest Bank'!I5 -> 825438.09 | F3: =E3*H3 -> 825438.09 | H3: 1 | J3: Row Labels | K3: Sum of Amount (USD)
A4: 46023 | B4: SG | C4: AXT USD | D4: USD | E4: ='AXT - USD'!J5 -> 57825.83 | F4: =E4*H4 -> 57825.83 | H4: 1 | J4: Jan | K4: 1955526.2
A5: 46023 | B5: SG | C5: AXT SGD | D5: SGD | E5: ='AXT- SGD'!I5 -> 173074.36 | F5: =E5*H5 -> 136265.08 | H5: 0.787321 | J5: CN | K5: 163686.69
A6: 46023 | B6: SG | C6: AXT CNY | D6: CNY | E6: 14245.44 | F6: =E6*H6 -> 2049.2778 | H6: =FOREX!K2 -> 0.143855 | J6: AXS CNY | K6: 123483.85
A7: 46023 | B7: MY | C7: AXI USD | D7: USD | E7: ='AXI - USD'!I6 -> 11798.62 | F7: =E7*H7 -> 11798.62 | H7: 1 | J7: AXS CNY - Capital Fund | K7: 40202.835
A8: 46023 | B8: MY | C8: AXI MYR | D8: MYR | E8: ='AXI - MYR'!I5 -> 351069.83 | F8: =E8*H8 -> 89090.289 | H8: =FOREX!G2 -> 0.253768 | J8: HQ | K8: 1350855.9
A9: 46023 | B9: CN | C9: AXS CNY - Capital Fund | D9: CNY | E9: 139733.88 | F9: =E9*H9 -> 20101.417 | H9: =FOREX!K2 -> 0.143855 | J9: East West | K9: 1350855.9
A10: 46023 | B10: CN | C10: AXS CNY | D10: CNY | E10: 301052.42 | F10: =E10*H10 -> 43307.896 | H10: =FOREX!K2 -> 0.143855 | J10: MY | K10: 145647.34
A11: 46053 | B11: HQ | C11: East West | D11: USD | E11: ='AXT -Eastwest Bank'!I10 -> 525417.86 | F11: =E11*H11 -> 525417.86 | H11: 1 | J11: AXI MYR | K11: 133649.45
A12: 46053 | B12: SG | C12: AXT USD | D12: USD | E12: ='AXT - USD'!J18 -> 12669.95 | F12: =E12*H12 -> 12669.95 | H12: 1 | J12: AXI USD | K12: 11997.89
A13: 46053 | B13: SG | C13: AXT SGD | D13: SGD | E13: ='AXT- SGD'!I66 -> 107296.56 | F13: =E13*H13 -> 84476.835 | H13: =FOREX!C2 -> 0.787321 | J13: SG | K13: 295336.25
A14: 46053 | B14: SG | C14: AXT CNY | D14: CNY | E14: =E6 -> 14245.44 | F14: =E14*H14 -> 2049.2778 | H14: =FOREX!K2 -> 0.143855 | J14: AXT CNY | K14: 4098.5555
A15: 46053 | B15: MY | C15: AXI USD | D15: USD | E15: ='AXI - USD'!I22 -> 199.27 | F15: =E15*H15 -> 199.27 | H15: 1 | J15: AXT SGD | K15: 220741.91
A16: 46053 | B16: MY | C16: AXI MYR | D16: MYR | E16: ='AXI - MYR'!I44 -> 175590.15 | F16: =E16*H16 -> 44559.161 | H16: =FOREX!G2 -> 0.253768 | J16: AXT USD | K16: 70495.78
A17: 46053 | B17: CN | C17: AXS CNY - Capital Fund | D17: CNY | E17: =E9 -> 139733.88 | F17: =E17*H17 -> 20101.417 | H17: =FOREX!K2 -> 0.143855 | J17: Feb | K17: 947096.7
A18: 46053 | B18: CN | C18: AXS CNY | D18: CNY | E18: ='AXS-CNY'!I44 -> 557338.69 | F18: =E18*H18 -> 80175.957 | H18: =FOREX!K2 -> 0.143855 | J18: CN | K18: 79998.145
A19: 46081 | B19: HQ | C19: East West | D19: USD | E19: ='AXT -Eastwest Bank'!I15 -> 525421.95 | F19: =E19*H19 -> 525421.95 | H19: 1 | J19: AXS CNY | K19: 59625.364
A20: 46081 | B20: SG | C20: AXT USD | D20: USD | E20: ='AXT - USD'!J18 -> 12669.95 | F20: =E20*H20 -> 12669.95 | H20: 1 | J20: AXS CNY - Capital Fund | K20: 20372.781
A21: 46081 | B21: SG | C21: AXT SGD | D21: SGD | E21: ='AXT- SGD'!I116 -> 85042.2 | F21: =E21*H21 -> 67235.554 | H21: =FOREX!C3 -> 0.790614 | J21: HQ | K21: 525421.95
A22: 46081 | B22: SG | C22: AXT CNY | D22: CNY | E22: =E6 -> 14245.44 | F22: =E22*H22 -> 2076.9424 | H22: =FOREX!K3 -> 0.145797 | J22: East West | K22: 525421.95
A23: 46081 | B23: MY | C23: AXI USD | D23: USD | E23: ='AXI - USD'!I22 -> 199.27 | F23: =E23*H23 -> 199.27 | H23: 1 | J23: MY | K23: 259694.16
A24: 46081 | B24: MY | C24: AXI MYR | D24: MYR | E24: ='AXI - MYR'!I99 -> 1010053.6 | F24: =E24*H24 -> 259494.89 | H24: =FOREX!G3 -> 0.256912 | J24: AXI MYR | K24: 259494.89
A25: 46081 | B25: CN | C25: AXS CNY - Capital Fund | D25: CNY | E25: =E17 -> 139733.88 | F25: =E25*H25 -> 20372.781 | H25: =FOREX!K3 -> 0.145797 | J25: AXI USD | K25: 199.27
A26: 46081 | B26: CN | C26: AXS CNY | D26: CNY | E26: ='AXS-CNY'!I75 -> 408961.53 | F26: =E26*H26 -> 59625.364 | H26: =FOREX!K3 -> 0.145797 | J26: SG | K26: 81982.446
A27: 46112 | B27: HQ | C27: East West | D27: USD | E27: ='AXT -Eastwest Bank'!I23 -> 675398.53 | F27: =E27*H27 -> 675398.53 | H27: 1 | J27: AXT CNY | K27: 2076.9424
A28: 46112 | B28: SG | C28: AXT USD | D28: USD | E28: ='AXT - USD'!J35 -> 66399.97 | F28: =E28*H28 -> 66399.97 | H28: 1 | J28: AXT SGD | K28: 67235.554
A29: 46112 | B29: SG | C29: AXT SGD | D29: SGD | E29: ='AXT- SGD'!I216 -> 99091.407 | F29: =E29*H29 -> 76810.307 | H29: =FOREX!C4 -> 0.775146 | J29: AXT USD | K29: 12669.95
A30: 46112 | B30: SG | C30: AXT CNY | D30: CNY | E30: 2245.44 | F30: =E30*H30 -> 325.49674 | H30: =FOREX!K4 -> 0.144959 | J30: Mar | K30: 987757.94
A31: 46112 | B31: MY | C31: AXI USD | D31: USD | E31: ='AXI - USD'!I27 -> 172.51 | F31: =E31*H31 -> 172.51 | H31: 1 | J31: CN | K31: 37017.301
A32: 46112 | B32: MY | C32: AXI MYR | D32: MYR | E32: ='AXI - MYR'!I155 -> 532919.67 | F32: =E32*H32 -> 131633.82 | H32: =FOREX!G4 -> 0.247005 | J32: AXS CNY | K32: 16759.085
A33: 46112 | B33: CN | C33: AXS CNY - Capital Fund | D33: CNY | E33: 139751.35 | F33: =E33*H33 -> 20258.216 | H33: =FOREX!K4 -> 0.144959 | J33: AXS CNY - Capital Fund | K33: 20258.216
A34: 46112 | B34: CN | C34: AXS CNY | D34: CNY | E34: ='AXS-CNY'!I100 -> 115612.59 | F34: =E34*H34 -> 16759.085 | H34: =FOREX!K4 -> 0.144959 | J34: HQ | K34: 675398.53
A35: 46142 | B35: HQ | C35: East West | D35: USD | E35: ='AXT -Eastwest Bank'!I30 -> 425377.12 | F35: =E35*H35 -> 425377.12 | H35: 1 | J35: East West | K35: 675398.53
A36: 46142 | B36: SG | C36: AXT USD | D36: USD | E36: ='AXT - USD'!J48 -> 124366.3 | F36: =E36*H36 -> 124366.3 | H36: 1 | J36: MY | K36: 131806.33
A37: 46142 | B37: SG | C37: AXT SGD | D37: SGD | E37: ='AXT- SGD'!I280 -> 121074.26 | F37: =E37*H37 -> 95028.247 | H37: =FOREX!C5 -> 0.78487574 | J37: AXI MYR | K37: 131633.82
A38: 46142 | B38: SG | C38: AXT CNY | D38: CNY | E38: =E30 -> 2245.44 | F38: =E38*H38 -> 328.80724 | H38: =FOREX!K5 -> 0.14643332 | J38: AXI USD | K38: 172.51
A39: 46142 | B39: MY | C39: AXI USD | D39: USD | E39: ='AXI - USD'!I27 -> 172.51 | F39: =E39*H39 -> 172.51 | H39: 1 | J39: SG | K39: 143535.77
A40: 46142 | B40: MY | C40: AXI MYR | D40: MYR | E40: ='AXI - MYR'!I188 -> 537094.84 | F40: =E40*H40 -> 135285.04 | H40: =FOREX!G5 -> 0.25188297 | J40: AXT CNY | K40: 325.49674
...

Sheet Actual Cash Inflow
A3: Sum of Amount (USD) | B3: Column Labels
B4: <11/12/2025 | C4: 2025 | D4: 2026 | J4: 2026 Total | K4: Grand Total
A5: Row Labels | D5: Jan | E5: Feb | F5: Mar | G5: Apr | H5: May | I5: Jun
A6: SG | B6: 610519.62 | D6: 9786.02 | E6: 26431.461 | F6: 29867.021 | G6: 43635.949 | H6: 139172.16 | I6: 278239.45 | J6: 527132.06 | K6: 1137651.7
A7: CN | C7: 80217.28 | D7: 80217.28 | H7: 61504.021 | J7: 141721.3 | K7: 221938.58
A8: MY | B8: 172939.19 | E8: 455699.68 | F8: 7743.3277 | G8: 51666.386 | H8: 967.91597 | J8: 516077.31 | K8: 689016.5
A9: Grand Total | B9: 783458.81 | C9: 80217.28 | D9: 90003.3 | E9: 482131.14 | F9: 37610.349 | G9: 95302.336 | H9: 201644.1 | I9: 278239.45 | J9: 1184930.7 | K9: 2048606.8

Sheet Forecast Cash Inflow
A1: Status | B1: (Multiple Items)
A3: Sum of Amount (USD) | B3: Column Labels
B4: 2026 | I4: 2026 Total | J4: 2027 | K4: Grand Total
A5: Row Labels | B5: Jun | C5: Jul | D5: Aug | E5: Sep | F5: Oct | G5: Nov | H5: Dec
A6: MY | B6: 76124.171 | D6: 96815.02 | I6: 172939.19 | K6: 172939.19
A7: SG | C7: 161048.15 | D7: 102750.48 | E7: 53729.594 | F7: 32666.627 | G7: 63621.872 | H7: 65300.745 | I7: 479117.47 | J7: 67315.392 | K7: 546432.86
A8: Grand Total | B8: 76124.171 | C8: 161048.15 | D8: 199565.5 | E8: 53729.594 | F8: 32666.627 | G8: 63621.872 | H8: 65300.745 | I8: 652056.66 | J8: 67315.392 | K8: 719372.05

Sheet Revenue
A1: Status | B1: (Multiple Items)
A3: Sum of Amount (USD) | B3: Column Labels
B4: 2025 | C4: 2026 | I4: 2026 Total | J4: Grand Total
A5: Row Labels | C5: Jan | D5: Feb | E5: Mar | F5: Apr | G5: May | H5: Jun
A6: CN | B6: 160434.56 | F6: 1403.5877 | G6: 60100.433 | I6: 61504.021 | J6: 221938.58
A7: MY | B7: 507366.06 | D7: 7743.3277 | G7: 173907.11 | I7: 181650.44 | J7: 689016.5
A8: SG | B8: 9786.02 | C8: 33874.465 | D8: 43635.949 | E8: 69308.043 | F8: 248280.53 | G8: 308945.73 | H8: 34216.365 | I8: 738261.09 | J8: 748047.11
A9: Grand Total | B9: 677586.64 | C9: 33874.465 | D9: 51379.277 | E9: 69308.043 | F9: 249684.12 | G9: 542953.28 | H9: 34216.365 | I9: 981415.54 | J9: 1659002.2

Sheet AR
A1: Alpha X Technology Pte Ltd (Singapore) | J1: SGD | K1: 0.77012503
A2: Status | B2: Entity | C2: Invoice Date | D2: Due Date | E2: Expected Inflow | F2: Payment Received Date | G2: Currency | H2: Sub Total | I2: Tax | J2: Total Amount | K2: Amount (USD) | L2: Client Name | M2: Invoice Number | N2: Description | O2: Project Code | Q2: Account Code | R2: Account Category | S2: Department | T2: SST | U2: Remarks
A3: Paid | B3: SG | C3: 46021 | D3: 46051 | E3: 46049 | F3: 46049 | G3: USD | H3: 8978 | I3: 808.02 | J3: =H3+I3 -> 9786.02 | K3: =IF(G3="SGD", J3*$K$1, J3) -> 9786.02 | L3: Soitec Microelectronics Singapore Pte Ltd | M3: INV 2512002 | N3: Development Support Services for PR1 Visual Inspect automation - December 2025 | O3: Soitec 001-202501- PR1 ADSS | P3: SG-00017-7 | Q3: Revenue | R3: Revenue | S3: Sales & Pre-sales | T3: Yes
A4: Paid | B4: SG | C4: 46043 | D4: 46073 | E4: 46108 | F4: 46108 | G4: SGD | H4: 8866.67 | I4: 798 | J4: =H4+I4 -> 9664.67 | K4: =IF(G4="SGD", J4*$K$1, J4) -> 7443.0043 | L4: VisionPower Semiconductor Manufacturing Company Pte Ltd | M4: INV 2601001 | N4: Power BI Consultant Fees - December 2025 | O4: VSMC 001-202508-Power BI | P4: SG-00010-1 | Q4: Revenue | R4: Revenue | S4: Sales & Pre-sales | T4: Yes
A5: Paid | B5: SG | C5: 46044 | D5: 46074 | E5: 46080 | F5: 46080 | G5: SGD | H5: 5000 | I5: 0 | J5: =H5+I5 -> 5000 | K5: =IF(G5="SGD", J5*$K$1, J5) -> 3850.6252 | L5: Armstrong Industrial Corporation Limited | M5: INV 2601002 | N5: AX JIT - IOT BOX (Tianjin) | O5: Armstrong 002-202509- AX JIT (AEM) | P5: SG-00031-1 | Q5: Revenue | R5: Revenue | S5: R&D - Team D | T5: No
A6: Paid | B6: SG | C6: 46052 | D6: 46082 | E6: 46080 | F6: 46080 | G6: SGD | H6: 26900 | I6: 2421 | J6: =H6+I6 -> 29321 | K6: =IF(G6="SGD", J6*$K$1, J6) -> 22580.836 | L6: Armstrong Industrial Corporation Limited | M6: INV 2601003 | N6: Implementation fees - CN Suzhou (Part 2) | O6: Armstrong 001-202508-MES | P6: SG-00008-Suzhou-2 | Q6: Revenue | R6: Revenue | S6: R&D - Team D | T6: Yes
A7: Paid | B7: SG | C7: 46056 | D7: 46086 | E7: 46142 | F7: 46140 | G7: SGD | H7: 8866.67 | I7: 798 | J7: =H7+I7 -> 9664.67 | K7: =IF(G7="SGD", J7*$K$1, J7) -> 7443.0043 | L7: VisionPower Semiconductor Manufacturing Company Pte Ltd | M7: INV 2602001 | N7: Power BI Consultant Fees - January 2026 | O7: VSMC 001-202508-Power BI | P7: SG-00010-2 | Q7: Revenue | R7: Revenue | S7: Sales & Pre-sales | T7: Yes
A8: Paid | B8: SG | C8: 46056 | D8: 46086 | E8: 46091 | F8: 46091 | G8: USD | H8: 8978 | I8: 808.02 | J8: =H8+I8 -> 9786.02 | K8: =IF(G8="SGD", J8*$K$1, J8) -> 9786.02 | L8: Soitec Microelectronics Singapore Pte Ltd | M8: INV 2602002 | N8: Development Support Services for PR1 Visual Inspect automation - January 2026 | O8: Soitec 001-202501- PR1 ADSS | P8: SG-00017-8 | Q8: Revenue | R8: Revenue | S8: Sales & Pre-sales | T8: Yes
A9: Paid | B9: SG | C9: 46062 | D9: 46092 | E9: 46142 | F9: 46125 | G9: SGD | H9: 26900 | I9: 2421 | J9: =H9+I9 -> 29321 | K9: =IF(G9="SGD", J9*$K$1, J9) -> 22580.836 | L9: Armstrong Industrial Corporation Limited | M9: INV 2602003 | N9: Implementation fees - CN Tianjin (UAT Completion) | O9: Armstrong 001-202508-MES | P9: SG-00008-Tianjin-5 | Q9: Revenue | R9: Revenue | S9: R&D - Team D | T9: Yes
A10: Paid | B10: SG | C10: 46063 | D10: 46093 | E10: 46142 | F10: 46125 | G10: SGD | H10: 2609.69 | I10: 234.87 | J10: =H10+I10 -> 2844.56 | K10: =IF(G10="SGD", J10*$K$1, J10) -> 2190.6669 | L10: Armstrong Industrial Corporation Limited | M10: INV 2602004 | N10: Consultation Fee : AOT 17th Nov to 21st Nov 2025 | O10: Armstrong 001-202508-MES | Q10: Revenue | R10: Revenue | S10: R&D - Team D | T10: Yes
A11: Paid | B11: SG | C11: 46080 | D11: 46110 | E11: 46142 | F11: 46125 | G11: SGD | H11: 1948.24 | I11: 175.34 | J11: =H11+I11 -> 2123.58 | K11: =IF(G11="SGD", J11*$K$1, J11) -> 1635.4221 | L11: Armstrong Industrial Corporation Limited | M11: INV 2602005 | N11: Consultation Fee: AOT and ATS 4th Jan - 16th Jan 2026 | O11: Armstrong 001-202508-MES | Q11: Revenue | R11: Revenue | S11: R&D - Team D | T11: Yes
A12: Paid | B12: SG | C12: 46084 | D12: 46114 | E12: 46142 | F12: 46154 | G12: SGD | H12: 585.13 | I12: 52.66 | J12: =H12+I12 -> 637.79 | K12: =IF(G12="SGD", J12*$K$1, J12) -> 491.17804 | L12: Armstrong Industrial Corporation Limited | M12: INV 2603001 | N12: Consultation Fee : ATS Go Live 2 Feb - 6 Feb 2026. | O12: Armstrong 001-202508-MES | Q12: Revenue | R12: Revenue | S12: R&D - Team D | T12: Yes
A13: Paid | B13: SG | C13: 46084 | D13: 46114 | E13: 46142 | F13: 46149 | G13: SGD | H13: 8866.67 | I13: 798 | J13: =H13+I13 -> 9664.67 | K13: =IF(G13="SGD", J13*$K$1, J13) -> 7443.0043 | L13: VisionPower Semiconductor Manufacturing Company Pte Ltd | M13: INV 2603002 | N13: Power BI Consultant Fees - February 2026 | O13: VSMC 001-202508-Power BI | P13: SG-00010-3 | Q13: Revenue | R13: Revenue | S13: Sales & Pre-sales | T13: Yes
A14: Paid | B14: SG | C14: 46086 | D14: 46116 | E14: 46107 | F14: 46107 | G14: USD | H14: 8978 | I14: 808.02 | J14: =H14+I14 -> 9786.02 | K14: =IF(G14="SGD", J14*$K$1, J14) -> 9786.02 | L14: Soitec Microelectronics Singapore Pte Ltd | M14: INV 2603003 | N14: Development Support Services for PR1 Visual Inspect automation - February 2025 | O14: Soitec 001-202501- PR1 ADSS | P14: SG-00017-9 | Q14: Revenue | R14: Revenue | S14: Sales & Pre-sales | T14: Yes
A15: Paid | B15: SG | C15: 46087 | D15: 46117 | E15: 46090 | F15: 46090 | G15: SGD | H15: 2099 | I15: 188.91 | J15: =H15+I15 -> 2287.91 | K15: =IF(G15="SGD", J15*$K$1, J15) -> 1761.9768 | L15: Infinix Hospitality Management Pte Ltd | M15: INV 2603004 | N15: AI Scheduler Setup Fee (Phase 1) + AI Scheduler Monthly Subscription | O15: Infinix 001-202603-AX trace | P15: SG-00045-1 | Q15: Revenue | R15: Revenue | S15: R&D - Team D | T15: Yes
A16: Paid | B16: SG | C16: 46093 | D16: 46123 | E16: 46142 | F16: 46154 | G16: SGD | H16: 46400 | I16: 4176 | J16: =H16+I16 -> 50576 | K16: =IF(G16="SGD", J16*$K$1, J16) -> 38949.844 | L16: Armstrong Industrial Corporation Limited | M16: INV 2603005 | N16: Implementation Fees – CN Changchun (Kick Off) | O16: Armstrong 001-202508-MES | P16: SG-00008-Changchun-7 | Q16: Revenue | R16: Revenue | S16: R&D - Team D | T16: Yes
A17: Paid | B17: SG | C17: 46094 | D17: 46124 | E17: 46107 | F17: 46107 | G17: USD | H17: 1000 | I17: 90 | J17: =H17+I17 -> 1090 | K17: =IF(G17="SGD", J17*$K$1, J17) -> 1090 | L17: Gtrontec Technology Pte Ltd | M17: INV 2603006 | N17: AX Trace Digital Marketing Solution 19 Feb 2026 – 18 Mar 2026 (1/6) | O17: GT 002-202602-AX Trace Digital Mktg Solution | P17: SG-00041-1 | R17: Revenue | S17: R&D - Team D | T17: Yes
A18: Paid | B18: SG | C18: 46111 | D18: 46141 | E18: 46173 | F18: 46139 | G18: USD | H18: 8978 | I18: 808.02 | J18: =H18+I18 -> 9786.02 | K18: =IF(G18="SGD", J18*$K$1, J18) -> 9786.02 | L18: Soitec Microelectronics Singapore Pte Ltd | M18: INV 2603007 | N18: Development Support Services for PR1 Visual Inspect automation - March 2026 | O18: Soitec 001-202501- PR1 ADSS | P18: SG-00017-10 | Q18: Revenue | R18: Revenue | S18: Sales & Pre-sales | T18: Yes
A19: Paid | B19: SG | C19: 46113 | D19: 46143 | E19: 46173 | F19: 46170 | G19: SGD | H19: 8866.67 | I19: 798 | J19: =H19+I19 -> 9664.67 | K19: =IF(G19="SGD", J19*$K$1, J19) -> 7443.0043 | L19: VisionPower Semiconductor Manufacturing Company Pte Ltd | M19: INV 2604001 | N19: Power BI Consultant Fees - March 2026 | O19: VSMC 001-202508-Power BI (1st)
A20: Paid | B20: SG | C20: 46113 | D20: 46143 | E20: 46173 | F20: 46170 | G20: SGD | H20: 8866.67 | I20: 798 | J20: =H20+I20 -> 9664.67 | K20: =IF(G20="SGD", J20*$K$1, J20) -> 7443.0043 | L20: VisionPower Semiconductor Manufacturing Company Pte Ltd | M20: INV 2604002 | N20: Power BI Consultant Fees - March 2026 | O20: VSMC 004-202603-Power BI (2nd)
A21: Paid | B21: SG | C21: 46113 | D21: 46143 | E21: 46173 | F21: 46188 | G21: SGD | H21: 16000 | I21: 1440 | J21: =H21+I21 -> 17440 | K21: =IF(G21="SGD", J21*$K$1, J21) -> 13430.981 | L21: Armstrong Industrial Corporation Limited | M21: INV 2604003 | N21: Project milestone: Phase 1 - 40% upon kick off AX Trace Smart Factory Data Platform | O21: Armstrong 004-202603-AX Trace Smart Factory Data Platform
A22: Declined | B22: SG | C22: 46119 | D22: 46127 | E22: 46142 | G22: SGD | H22: 76345 | I22: 6871.05 | J22: =H22+I22 -> 83216.05 | K22: =IF(G22="SGD", J22*$K$1, J22) -> 64086.763 | L22: Gtrontec Technology Pte Ltd | M22: INV 2604004 | N22: OHT related IP License Fee for 2 years | O22: Nil
A23: Due | B23: SG | C23: 46121 | D23: 46151 | E23: 46234 | G23: SGD | H23: 10800 | I23: 972 | J23: =H23+I23 -> 11772 | K23: =IF(G23="SGD", J23*$K$1, J23) -> 9065.9119 | L23: Armstrong Industrial Corporation Limited | M23: INV 2604005 | N23: Implementation Fees - MY JB (Kick Off) | O23: Armstrong 001-202508-MES
A24: Due | B24: SG | C24: 46121 | D24: 46151 | E24: 46234 | G24: SGD | H24: 46400 | I24: 4176 | J24: =H24+I24 -> 50576 | K24: =IF(G24="SGD", J24*$K$1, J24) -> 38949.844 | L24: Armstrong Industrial Corporation Limited | M24: INV 2604006 | N24: Implementation Fees - MY JB (Kick Off) | O24: Armstrong 001-202508-MES
A25: Due | B25: SG | C25: 46121 | D25: 46151 | E25: 46234 | G25: SGD | H25: 40000 | I25: 3600 | J25: =H25+I25 -> 43600 | K25: =IF(G25="SGD", J25*$K$1, J25) -> 33577.451 | L25: Armstrong Industrial Corporation Limited | M25: INV 2604007 | N25: Implementation Fees - CN Wuhan | O25: Armstrong 001-202508-MES
A26: Paid | B26: SG | C26: 46122 | D26: 46152 | E26: 46173 | F26: 46153 | G26: SGD | H26: 99 | I26: 8.91 | J26: =H26+I26 -> 107.91 | K26: =IF(G26="SGD", J26*$K$1, J26) -> 83.104192 | L26: Infinix Hospitality Management Pte Ltd | M26: INV 2604008 | N26: Ax Trace AI Scheduler Monthly Subscription - April 2026 (2/6) | O26: Infinix 001-202603-AX trace | P26: SG-00045-2 | Q26: Revenue | R26: Revenue | S26: R&D - Team D | T26: Yes
A27: Paid | B27: SG | C27: 46126 | D27: 46156 | E27: 46173 | F27: 46155 | G27: USD | H27: 1000 | I27: 90 | J27: =H27+I27 -> 1090 | K27: =IF(G27="SGD", J27*$K$1, J27) -> 1090 | L27: Gtrontec Technology Pte Ltd | M27: INV 2604009 | N27: Ax Trace Digital Marketing Solution a) Website content audit & revamp plan b) New LinkedIn page setup blog framework & ongoing blog / content creation (weekly) Period : 19 Mar 2026 – 18 Apr 2026 | O27: GT 002-202602-AX Trace Digital Mktg Solution | P27: AXQ00028 | Q27: Revenue | R27: Revenue | T27: Yes
A28: Paid | B28: SG | C28: 46133 | D28: 46163 | E28: 46173 | F28: 46199 | G28: SGD | H28: 8866.67 | I28: 798.0003 | J28: =H28+I28 -> 9664.6703 | K28: =IF(G28="SGD", J28*$K$1, J28) -> 7443.0045 | L28: VisionPower Semiconductor Manufacturing Company Pte Ltd | M28: INV 2604011 | N28: POWER BI CONSULTANTS AS QUO : AXQ00015 for the month of April 2026 | O28: VSMC 001-202508-Power BI (1st) | P28: PO 3325001371 | Q28: Revenue | R28: Revenue | T28: Yes
A29: Paid | B29: SG | C29: 46133 | D29: 46163 | E29: 46173 | F29: 46170 | G29: SGD | H29: 8866.67 | I29: 798.0003 | J29: =H29+I29 -> 9664.6703 | K29: =IF(G29="SGD", J29*$K$1, J29) -> 7443.0045 | L29: VisionPower Semiconductor Manufacturing Company Pte Ltd | M29: INV 2604012 | N29: 2nd POWER BI CONSULTANTS AS QUO : AXQ00015 for the month of April 2026 | O29: VSMC 004-202603-Power BI (2nd) | P29: PO 3325001593 | Q29: Revenue | R29: Revenue | T29: Yes
A30: Pending | B30: SG | C30: 46133 | D30: 46194 | E30: 46265 | G30: USD | H30: 56000 | I30: 5040 | J30: =H30+I30 -> 61040 | K30: =IF(G30="SGD", J30*$K$1, J30) -> 61040 | L30: Advanced Micro Foundry Pte Ltd | M30: INV 2604010 | N30: Implementation of Equipment Automation for 4 equipment types | O30: AMF 003-202506-EAS | P30: PO002149 Ver. 1.2 | Q30: Revenue | R30: Revenue | T30: Yes
A31: Due | B31: SG | C31: 46140 | D31: 46170 | E31: 46234 | G31: SGD | H31: 2705.65 | I31: 243.5085 | J31: =H31+I31 -> 2949.1585 | K31: =IF(G31="SGD", J31*$K$1, J31) -> 2271.2208 | L31: Armstrong Industrial Corporation Limited | M31: INV 2604013 | N31: Consultation Fee: Tianjin (AOT) Go-Live 4 Mar, and Changchun (AOC) kick off 9 Mar - 13 Mar 2026 | O31: Armstrong 001-202508-MES | P31: PO26M00038 | Q31: Revenue | R31: Revenue | T31: Yes
A32: Paid | B32: SG | C32: 46141 | D32: 46142 | E32: 46172 | F32: 46150 | G32: USD | H32: 59000 | I32: 0 | J32: =H32+I32 -> 59000 | K32: =IF(G32="SGD", J32*$K$1, J32) -> 59000 | L32: Shanghai Wilson Optimus Technology Co., Ltd., | M32: INV 2604014 | N32: Taiwan IP License | O32: Wilson 001-202604-IP Licenseout | Q32: Revenue | R32: Revenue
A33: Paid | B33: SG | C33: 46147 | D33: 46177 | E33: 46203 | F33: 46168 | G33: USD | H33: 8978 | I33: 808.02 | J33: =H33+I33 -> 9786.02 | K33: =IF(G33="SGD", J33*$K$1, J33) -> 9786.02 | L33: Soitec Microelectronics Singapore Pte Ltd | M33: INV 2605001 | N33: Development Support Services for PR1 Visual Inspect automation - April 2026 | O33: Soitec 001-202501- PR1 ADSS | P33: SG-00017-11 | Q33: Revenue | R33: Revenue
A34: Paid | B34: SG | C34: 46150 | D34: 46180 | E34: 46203 | F34: 46176 | G34: CNY | H34: 1575966.3 | I34: 0 | J34: =H34+I34 -> 1575966.3 | K34: 232853.75 | L34: Getech (ShenZhen) Co., Ltd | M34: INV 2605002 | N34: Technical Service Fee - 50% kick off payment | O34: GT 001-202604-Resources Service | Q34: Revenue | R34: Revenue
A35: Pending | B35: SG | C35: 46157 | D35: 46187 | E35: 46234 | G35: SGD | H35: 18800 | I35: 1692 | J35: =H35+I35 -> 20492 | K35: =IF(G35="SGD", J35*$K$1, J35) -> 15781.402 | L35: Armstrong Industrial Corporation Limited | M35: INV 2605003 | N35: Implementation Fees – CHN ChangChun (UAT) | O35: Armstrong 001-202508-MES | P35: PO25M00126 | Q35: Revenue | R35: Revenue | T35: Yes
A36: Pending | B36: SG | C36: 46157 | D36: 46187 | E36: 46234 | G36: SGD | H36: 8100 | I36: 729 | J36: =H36+I36 -> 8829 | K36: =IF(G36="SGD", J36*$K$1, J36) -> 6799.4339 | L36: Armstrong Industrial Corporation Limited | M36: INV 2605004 | N36: Implementation Fees – MY JB (UAT) | O36: Armstrong 001-202508-MES | P36: PO26M00034 | Q36: Revenue | R36: Revenue | T36: Yes
A37: Pending | B37: SG | C37: 46157 | D37: 46187 | E37: 46234 | G37: SGD | H37: 18800 | I37: 1692 | J37: =H37+I37 -> 20492 | K37: =IF(G37="SGD", J37*$K$1, J37) -> 15781.402 | L37: Armstrong Industrial Corporation Limited | M37: INV 2605005 | N37: Implementation Fees – MY JB (UAT) | O37: Armstrong 001-202508-MES | P37: PO25M00126 | Q37: Revenue | R37: Revenue | T37: Yes
A38: Forecast | B38: SG | C38: 46157 | D38: 46218 | E38: 46233 | G38: USD | J38: =H38+I38 -> 0 | K38: =IF(G38="SGD", J38*$K$1, J38) -> 0 | L38: Advanced Micro Foundry Pte Ltd | M38: N/A | N38: 20% payment (every 4 tools) | O38: AMF 003-202506-EAS | P38: SG-00005-2
A39: Forecast | B39: SG | C39: 46157 | D39: 46218 | E39: 46233 | G39: USD | J39: =H39+I39 -> 0 | K39: =IF(G39="SGD", J39*$K$1, J39) -> 0 | L39: Advanced Micro Foundry Pte Ltd | M39: N/A | N39: 20% payment (1 tool only) | O39: AMF 003-202506-EAS | P39: SG-00005-3
A40: Paid | B40: SG | C40: 46164 | D40: 46194 | E40: 46203 | F40: 46202 | G40: SGD | H40: 2599 | I40: 233.91 | J40: =H40+I40 -> 2832.91 | K40: =IF(G40="SGD", J40*$K$1, J40) -> 2181.6949 | L40: Infinix Hospitality Management Pte Ltd | M40: INV 2605006 | N40: Ax Trace AI Scheduler Monthly Subscription - May 2026 (3/6) | O40: Infinix 001-202603-AX trace | P40: SG-00045-3 | Q40: Revenue | R40: Revenue | S40: R&D - Team D | T40: Yes
...

Sheet Detail1
A1: Details for Sum of Amount (USD) - Entity: MY, Group: ERROR, Months (Payment Date/ Planned Date ): May, Years (Payment Date/ Planned Date ): 2026, Status: Paid (+)
A3: Status | B3: Entity | C3: Billing Date | D3: Due Date | E3: Payment Date/ Planned Date | F3: Currency | G3: Sub Total | H3: Tax | I3: Total Amount | J3: Amount (USD) | K3: Payee | L3: Invoice Number | M3: Description | N3: Account Code | O3: Account Category | P3: Department | Q3: Group | R3: Submitter | S3: Approval | T3: Authorisation | U3: Remarks | V3: GST Claimable
A4: Paid | B4: MY | C4: 46173 | D4: 46173 | E4: 46171 | F4: MYR | J4: 15742.95 | K4: MY Staff | L4: Net Pay - May 2026 | M4: Net Pay - May 2026 | N4: Salaries & Wages | O4: Headcount Costs | P4: R&D - MY Team | Q4: ERROR

Sheet Actual Cash Outflow
A1: Status | B1: Paid
A2: Amount (USD) | B2: (Multiple Items)
A4: Sum of Amount (USD) | B4: Column Labels
B5: 2026 | H5: 2026 Total | I5: Grand Total
A6: Row Labels | B6: Jan | C6: Feb | D6: Mar | E6: Apr | F6: May | G6: Jun
A7: DSC | B7: 26646.327 | C7: 11781.977 | D7: 132634.77 | E7: 28722.289 | F7: 13277.291 | G7: 3505.3275 | H7: 216567.98 | I7: 216567.98
A8: SG | B8: 20532.76 | C8: 5797.04 | D8: 78660.742 | E8: 22263.5 | F8: 5811.7935 | H8: 133065.84 | I8: 133065.84
A9: Employee Benefits | F9: 49.353546 | H9: 49.353546 | I9: 49.353546
A10: Staff Welfare - Gift & Tokens | F10: 49.353546 | H10: 49.353546 | I10: 49.353546
A11: Headcount Costs | B11: 20532.76 | C11: 5797.04 | D11: 37639.17 | E11: 22263.5 | F11: 5762.44 | H11: 91994.91 | I11: 91994.91
A12: Salaries & Wages | B12: 20532.76 | C12: 3053.23 | D12: 37329.25 | E12: 16700.13 | F12: 5.43 | H12: 77620.8 | I12: 77620.8
A13: Statutory Contribution | C13: 2743.81 | D13: 309.92 | E13: 5563.37 | F13: 5757.01 | H13: 14374.11 | I13: 14374.11
A14: Travelling Expenses | D14: 41021.572 | H14: 41021.572 | I14: 41021.572
A15: Transportation fee - National | D15: 41021.572 | H15: 41021.572 | I15: 41021.572
A16: MY | B16: 6113.5671 | C16: 5984.9373 | D16: 53974.03 | E16: 6458.7886 | F16: 7465.497 | G16: 3505.3275 | H16: 83502.148 | I16: 83502.148
A17: General & Administrative | B17: 322851.76 | C17: 275433.43 | D17: 238343.26 | E17: 129925.27 | F17: 264494.88 | G17: 1.0460758e+09 | H17: 1.0473069e+09 | I17: 1.0473069e+09
A18: SG | B18: 145791.4 | C18: 53522.87 | D18: 206138.89 | E18: 112710.01 | F18: 242949.16 | G18: 1.0459179e+09 | H18: 1.046679e+09 | I18: 1.046679e+09
A19: Accrual | F19: 19716.608 | H19: 19716.608 | I19: 19716.608
A20: Accrual | F20: 19716.608 | H20: 19716.608 | I20: 19716.608
A21: Accrual - Expenses of 2025 | B21: 40570.651 | G21: 120800.18 | H21: 161370.83 | I21: 161370.83
A22: Accrual - Expenses of 2025 | B22: 40570.651 | G22: 120800.18 | H22: 161370.83 | I22: 161370.83
A23: Bank | F23: 180760.77 | G23: 62000 | H23: 242760.77 | I23: 242760.77
A24: OCBC SG - SGD | F24: 180760.77 | G24: 62000 | H24: 242760.77 | I24: 242760.77
A25: Bank Charges | B25: 119.44452 | C25: 0.30225956 | D25: 99.85226 | E25: 39.44226 | F25: 40.89226 | G25: 23.27226 | H25: 323.20582 | I25: 323.20582
A26: Bank Charges | B26: 119.44452 | C26: 0.30225956 | D26: 99.85226 | E26: 39.44226 | F26: 40.89226 | G26: 23.27226 | H26: 323.20582 | I26: 323.20582
A27: Corporate Tax Expenses | D27: 8853.79 | H27: 8853.79 | I27: 8853.79
A28: Corporate Income Tax Expenses | D28: 8853.79 | H28: 8853.79 | I28: 8853.79
A29: Courier Charges | B29: 101.96177 | D29: 65.337408 | F29: 55.174892 | H29: 222.47407 | I29: 222.47407
A30: Courier Charges | B30: 101.96177 | D30: 65.337408 | F30: 55.174892 | H30: 222.47407 | I30: 222.47407
A31: Current Asset | D31: 138.70722 | H31: 138.70722 | I31: 138.70722
A32: Prepayment | D32: 138.70722 | H32: 138.70722 | I32: 138.70722
A33: Direct Costs | G33: 1.0435574e+09 | H33: 1.0435574e+09 | I33: 1.0435574e+09
A34: Contract Services - Project delivery | G34: 1.0435574e+09 | H34: 1.0435574e+09 | I34: 1.0435574e+09
A35: Employee Benefits | B35: 6720.698 | C35: 11950.492 | D35: 25811.694 | E35: 4185.3138 | F35: 3620.4232 | G35: 684626.63 | H35: 736915.25 | I35: 736915.25
A36: Insurance expenses | B36: 1106.0522 | C36: 8254.177 | D36: 24285.978 | E36: 2403.7605 | F36: 1114.4972 | H36: 37164.464 | I36: 37164.464
A37: Staff Welfare - Gift & Tokens | C37: 200.23251 | D37: 61.53299 | E37: 133.18542 | F37: 49.089996 | H37: 444.04092 | I37: 444.04092
A38: Staff Welfare - Meal & Refreshment | B38: 1464.0234 | C38: 3218.8839 | D38: 1346.6623 | E38: 1648.3679 | F38: 1442.0586 | G38: 684626.63 | H38: 693746.63 | I38: 693746.63
A39: Staff Welfare - Medical Expenses | B39: 4150.6225 | D39: 117.52108 | H39: 4268.1435 | I39: 4268.1435
A40: Staff Welfare - Recreation, Training & Events | C40: 277.1988 | F40: 1014.7774 | H40: 1291.9762 | I40: 1291.9762
A41: General Expenses | E41: 4.2356877 | F41: 43.020603 | H41: 47.256291 | I41: 47.256291
...

Sheet Forecast Cash Outflow
A1: Status | B1: (Multiple Items)
A3: Row Labels | B3: Sum of Amount (USD)
A4: 2026 | B4: 2072175.3
A5: Jun | B5: 339241.5
A6: 46188 | B6: 8916.2844
A7: CN | B7: 8916.2844
A8: 46198 | B8: 2035
A9: MY | B9: 2035
A10: 46203 | B10: 328290.21
A11: SG | B11: 242514.34
A12: CN | B12: 23650.33
A13: MY | B13: 62125.541
A14: Jul | B14: 305694.94
A15: 46218 | B15: 4164.4003
A16: CN | B16: 90.2
A17: MY | B17: 4074.2003
A18: 46228 | B18: 33724.633
A19: SG | B19: 31968.369
A20: MY | B20: 1756.2645
A21: 46233 | B21: 113.55729
A22: SG | B22: 113.55729
A23: 46234 | B23: 267692.35
A24: SG | B24: 195644.93
A25: CN | B25: 4150.33
A26: MY | B26: 67897.094
A27: Aug | B27: 301533.5
A28: 46249 | B28: 4074.2003
A29: MY | B29: 4074.2003
A30: 46259 | B30: 35322.091
A31: SG | B31: 31109.176
A32: MY | B32: 4212.9145
A33: 46265 | B33: 262137.21
A34: SG | B34: 182987.21
A35: MY | B35: 79150
A36: Sep | B36: 264694.5
A37: 46280 | B37: 4074.2003
A38: MY | B38: 4074.2003
A39: 46290 | B39: 35322.091
A40: SG | B40: 31109.176
A41: MY | B41: 4212.9145
...

Sheet COGS
A1: Status | B1: Paid
A2: Group | B2: DSC
A4: Row Labels | B4: Sum of Amount (USD)
A5: 2026 | B5: 219507.67
A6: Jan | B6: 26646.327
A7: MY | B7: 6113.5671
A8: SG | B8: 20532.76
A9: Headcount Costs | B9: 20532.76
A10: Feb | B10: 11781.977
A11: MY | B11: 5984.9373
A12: SG | B12: 5797.04
A13: Headcount Costs | B13: 5797.04
A14: Mar | B14: 132634.77
A15: MY | B15: 53974.03
A16: SG | B16: 78660.742
... A35: Grand Total | B35: 219507.67

Sheet Expenses
A1: Status | B1: (All)
A3: Row Labels | B3: Sum of Amount (USD)
A4: 2026
A5: Jan
A6: CN | B6: -64687.108
A7: General & Administrative | B7: 2232.48
A8: Finance | B8: 344.51834
A9: Bank Charges | B9: 4.6119913
A10: Bank Charges | B10: 4.6119913
A11: Headcount Costs | B11: 96.590001
A12: Statutory Contribution | B12: 96.590001
A13: Other Income | B13: -54.941102
A14: Interest Income | B14: -54.941102
A15: Subscription Fee | B15: 298.25745
A16: Subscription Fee | B16: 298.25745
A17: General | B17: 1735.2049
... A255: Grand Total | B255: 7.830918e+08

Sheet Detail3
A1: Details for Sum of Amount (USD) - Account Category: Direct Costs, Entity: SG, Months (Payment Date/ Planned Date ): Jun, Years (Payment Date/ Planned Date ): 2026, Department : Business Operation (+)
A3: Status | B3: Entity | C3: Billing Date | D3: Due Date | E3: Payment Date/ Planned Date | F3: Currency | G3: Sub Total | H3: Tax | I3: Total Amount | J3: Amount (USD) | K3: Payee | L3: Invoice Number | M3: Description | N3: Account Code | O3: Account Category | P3: Department | Q3: Group | R3: Submitter | S3: Approval | T3: Authorisation | U3: Remarks | V3: GST Claimable
A4: Paid | B4: SG | C4: 46140 | D4: 46185 | E4: 46185 | F4: SGD | G4: 245688 | H4: 22111.92 | I4: 267799.92 | J4: 267799.92 | K4: ABeam Consulting (Singapore) Pte Ltd | L4: 1200312539 | M4: Purchase of S4 HAHA PMC License - SAP Finance Base - SAP Supply Chain Base - SAP Integration Suite,Standard edition - SAP AI Unit | N4: Contract Services - Project delivery | O4: Direct Costs | P4: Finance | Q4: General & Administrative

Sheet Detail4
A1: Details for Sum of Amount (USD) - Account Category: Accrual, Entity: SG, Months (Payment Date/ Planned Date ): May, Years (Payment Date/ Planned Date ): 2026, Department : Business Operation (+)
A3: Status | B3: Entity | C3: Billing Date | D3: Due Date | E3: Payment Date/ Planned Date | F3: Currency | G3: Sub Total | H3: Tax | I3: Total Amount | J3: Amount (USD) | K3: Payee | L3: Invoice Number | M3: Description | N3: Account Code | O3: Account Category | P3: Department | Q3: Group | R3: Submitter | S3: Approval | T3: Authorisation | U3: Remarks | V3: GST Claimable
A4: Paid | B4: SG | C4: 46161 | D4: 46171 | E4: 46170 | F4: SGD | G4: 16377.27 | H4: 0 | I4: 16377.27 | J4: 12612.55 | K4: Iras-Income Tax | L4: Payment Slip Number 25530286881052 | M4: Directive to Pay Tax for Wu WenLong | N4: Accrual | O4: Accrual | P4: HR | Q4: General & Administrative | R4: OCBC SGD
A5: Paid | B5: SG | C5: 46148 | D5: 46160 | E5: 46160 | F5: SGD | G5: 9164.8 | H5: 0 | I5: 9164.8 | J5: 7104.0581 | K5: Iras-Income Tax | L5: Payment Slip Number 25530281007030 | M5: Directive to Pay Tax for Jin Chao | N5: Accrual | O5: Accrual | P5: HR | Q5: General & Administrative

Sheet Detail5
A1: Details for Sum of Amount (USD) - Account Code : Accrual - Expenses of 2025, Account Category: Accrual - Expenses of 2025, Months (Payment Date/ Planned Date ): Jun, Years (Payment Date/ Planned Date ): 2026, Department : Business Operation (+)
A3: Status | B3: Entity | C3: Billing Date | D3: Due Date | E3: Payment Date/ Planned Date | F3: Currency | G3: Sub Total | H3: Tax | I3: Total Amount | J3: Amount (USD) | K3: Payee | L3: Invoice Number | M3: Description | N3: Account Code | O3: Account Category | P3: Department | Q3: Group | R3: Submitter | S3: Approval | T3: Authorisation | U3: Remarks | V3: GST Claimable
A4: Paid | B4: SG | C4: 46182 | D4: 46195 | E4: 46185 | F4: SGD | G4: 31 | H4: 0 | I4: 31 | J4: 120800.18 | K4: SkillsFuture Singapore Agency | M4: Outstanding SDL Payable for year 2025 | N4: Accrual - Expenses of 2025 | O4: Accrual - Expenses of 2025 | P4: HR | Q4: General & Administrative

Sheet Sheet1
A1: Department | B1: (Multiple Items)
A3: Sum of Amount (USD) | B3: Column Labels
B4: 2026 | N4: 2027 | P4: Grand Total
A5: Row Labels | B5: Jan | C5: Feb | D5: Mar | E5: Apr | F5: May | G5: Jun | H5: Jul | I5: Aug | J5: Sep | K5: Oct | L5: Nov | M5: Dec | N5: Jan | O5: Mar
A6: Research & Development | B6: 6054.4613 | C6: 20774.941 | D6: 217454.25 | E6: 67557.145 | F6: 54299.694 | G6: -2.6493834e+08 | H6: 77244.646 | I6: 92784.335 | J6: 60784.335 | K6: 72279.103 | L6: 86545.67 | M6: 72279.103 | N6: 5256.1033 | P6: -2.6410502e+08
A7: SG | B7: 61707.677 | C7: -19687.567 | D7: 161699.23 | E7: 29546.165 | F7: 3964.144 | G7: -2.6499093e+08 | H7: 52744.646 | I7: 52284.335 | J7: 52284.335 | K7: 47779.103 | L7: 62045.67 | M7: 47779.103 | N7: 5256.1033 | P7: -2.6443353e+08
A8: Accrual - Expenses of 2025 | C8: 118.32201 | P8: 118.32201
A9: Accrual - Expenses of 2025 | C9: 118.32201 | P9: 118.32201
A10: Bank Charges | G10: 0.0077 | P10: 0.0077
A11: Bank Charges | G11: 0.0077 | P11: 0.0077
A12: Employee Benefits | C12: 21.563501 | G12: 149.2645 | P12: 170.828
A13: Insurance expenses | C13: 21.563501 | P13: 21.563501
A14: Staff Welfare - Medical Expenses | G14: 149.2645 | P14: 149.2645
A15: Headcount Costs | B15: 56907.16 | C15: 5535.06 | D15: 132626.35 | E15: 49403.7 | F15: 2331.64 | G15: 44448 | H15: 42523 | I15: 42523 | J15: 42523 | K15: 42523 | L15: 42523 | M15: 42523 | P15: 546389.91
A16: Salaries & Wages | B16: 56907.16 | C16: 2960.72 | D16: 132325.52 | E16: 36691.53 | F16: 2.33 | G16: 40003 | H16: 40003 | I16: 40003 | J16: 40003 | K16: 40003 | L16: 40003 | M16: 40003 | P16: 508908.26
A17: Staff Allowance | E17: 7701.2503 | G17: 1925 | P17: 9626.2503
A18: Statutory Contribution | C18: 2574.34 | D18: 300.83 | E18: 5010.92 | F18: 2329.31 | G18: 2520 | H18: 2520 | I18: 2520 | J18: 2520 | K18: 2520 | L18: 2520 | M18: 2520 | P18: 27855.4
A19: Intercompany | B19: 14.423721 | P19: 14.423721
A20: Intercompany - Alpha X (Shanghai) Technology Co Ltd | B20: 14.423721 | P20: 14.423721
A21: Network & Server | D21: 25829.335 | E21: 4696.5459 | G21: 5314.5819 | H21: 10221.646 | I21: 9761.3348 | J21: 9761.3348 | K21: 5256.1033 | L21: 19522.67 | M21: 5256.1033 | N21: 5256.1033 | P21: 100875.76
A22: Network & Server | D22: 25829.335 | E22: 4696.5459 | G22: 5314.5819 | H22: 10221.646 | I22: 9761.3348 | J22: 9761.3348 | K22: 5256.1033 | L22: 19522.67 | M22: 5256.1033 | N22: 5256.1033 | P22: 100875.76
A23: Office Supplies | B23: 40.940692 | F23: 84.614937 | P23: 125.55563
A24: Consumable Tools | B24: 40.940692 | P24: 40.940692
A25: Office Supplies | F25: 84.614937 | P25: 84.614937
A26: Revenue | C26: -26431.461 | E26: -26406.925 | G26: -2.6504339e+08 | P26: -2.6509623e+08
A27: Sales - Services Fees | E27: -26406.925 | G27: -2.6504339e+08 | P27: -2.650698e+08
A28: Sales - Software | C28: -26431.461 | P28: -26431.461
A29: Sales Expenses | E29: 28.363705 | F29: 15.409902 | G29: 1242.934 | P29: 1286.7076
A30: Business Meals - International | E30: 28.363705 | F30: 15.409902 | P30: 43.773607
A31: Business Meals - National | G31: 1242.934 | P31: 1242.934
A32: Subscription Fee | B32: 4335.4067 | C32: 0 | D32: 125.0375 | E32: 275.29659 | F32: 173.05134 | G32: 95.4646 | P32: 5004.2567
A33: Subscription Fee | B33: 4335.4067 | C33: 0 | D33: 125.0375 | E33: 275.29659 | F33: 173.05134 | G33: 95.4646 | P33: 5004.2567
A34: Travelling Expenses | B34: 409.74547 | C34: 1068.9489 | D34: 3118.5058 | E34: 1549.1835 | F34: 1359.4278 | G34: 1206.4591 | P34: 8712.2706
A35: Accommodation - International | D35: 430.03012 | E35: 236.15884 | F35: 730.97818 | P35: 1397.1671
A36: Personal Meals - International | C36: 223.80604 | D36: 164.05203 | F36: 154.03701 | G36: 179.7873 | P36: 721.68238
A37: Transportation fee - International | B37: 368.41112 | C37: 719.95909 | D37: 2335.3271 | E37: 1206.1852 | F37: 388.01483 | G37: 988.6723 | P37: 6006.5697
A38: Transportation fee - National | B38: 41.334353 | C38: 125.18382 | D38: 189.0965 | E38: 106.83945 | F38: 86.397773 | G38: 37.9995 | P38: 586.85139
A39: CN | B39: -69957.271 | C39: 18164.18 | D39: 28817.26 | E39: 13019.82 | F39: 26600.6 | G39: 19500 | P39: 36144.589
A40: Employee Benefits | E40: 1006 | P40: 1006
A41: Staff Welfare - Meal & Refreshment | E41: 1006 | P41: 1006
...

Sheet Detail2
A1: Details for Sum of Amount (USD) - Account Category: Headcount Costs, Entity: MY, Group: ERROR, Years (Payment Date/ Planned Date ): 2026, Department : Business Operation (+)
A3: Status | B3: Entity | C3: Billing Date | D3: Due Date | E3: Payment Date/ Planned Date | F3: Currency | G3: Sub Total | H3: Tax | I3: Total Amount | J3: Amount (USD) | K3: Payee | L3: Invoice Number | M3: Description | N3: Account Code | O3: Account Category | P3: Department | Q3: Group | R3: Submitter | S3: Approval | T3: Authorisation | U3: Remarks | V3: GST Claimable
A4: Paid | B4: MY | C4: 46173 | D4: 46173 | E4: 46171 | F4: MYR | J4: 15742.95 | K4: MY Staff | L4: Net Pay - May 2026 | M4: Net Pay - May 2026 | N4: Salaries & Wages | O4: Headcount Costs | P4: R&D - MY Team | Q4: ERROR

Sheet Sheet5
A1: Department | B1: (All)
A3: Sum of Amount (USD) | B3: Column Labels
B4: 2026 | C4: 2027 | D4: Grand Total
A5: Row Labels
A6: DSC | B6: 431233.48 | D6: 431233.48
A7: MY | B7: 131037.15 | D7: 131037.15
A8: Direct Costs | B8: 47494.427 | D8: 47494.427
A9: Contract Services - Project delivery | B9: 47494.427 | D9: 47494.427
A10: Employee Benefits | B10: 376.30431 | D10: 376.30431
A11: Staff Welfare - Gift & Tokens | B11: 49.5625 | D11: 49.5625
A12: Staff Welfare - Meal & Refreshment | B12: 326.74181 | D12: 326.74181
A13: General Expenses | B13: 7.435 | D13: 7.435
A14: General Expenses | B14: 7.435 | D14: 7.435
A15: Headcount Costs | B15: 73903.076 | D15: 73903.076
A16: Salaries & Wages | B16: 61906.02 | D16: 61906.02
A17: Statutory Contribution | B17: 11997.056 | D17: 11997.056
... A40: Transportation fee - National | B40: 43730.382 | D40: 43730.382
A41: General & Administrative | B41: 1.0473674e+09 | C41: 22906.007 | D41: 1.0473903e+09
A42: CN | B42: 15329.584 | D42: 15329.584
A43: Bank Charges | B43: 35.751991 | D43: 35.751991
A44: Bank Charges | B44: 35.751991 | D44: 35.751991
A45: Courier Charges | B45: 23.498153 | D45: 23.498153
A46: Courier Charges | B46: 23.498153 | D46: 23.498153
A47: Employee Benefits | B47: 623.98009 | D47: 623.98009
A48: Insurance expenses | B48: 51.50009 | D48: 51.50009
A49: Staff Welfare - Gift & Tokens | B49: 136.69 | D49: 136.69
A50: Staff Welfare - Meal & Refreshment | B50: 435.79 | D50: 435.79
A51: Headcount Costs | B51: 1968.27 | D51: 1968.27
A52: Bank Charges | B52: 4.82 | D52: 4.82
A53: Salaries & Wages | B53: 1566.2 | D53: 1566.2
... A77: Professional & Consultancy Fees | B77: 62.24 | D77: 62.24
A78: MY | B78: 576724.06 | C78: 4330.5908 | D78: 581054.65
A79: Accrual | B79: 8795.22 | D79: 8795.22
A80: Accrual | B80: 8795.22 | D80: 8795.22
A81: Accrual - Expenses of 2025 | B81: 28969.618 | D81: 28969.618
A82: Accrual - Expenses of 2025 | B82: 28969.618 | D82: 28969.618
A83: Bank | B83: -57411.38 | D83: -57411.38
A84: OCBC MY - USD | B84: -57411.38 | D84: -57411.38
A85: Bank Charges | B85: 48.737741 | D85: 48.737741
A86: Bank Charges | B86: 48.737741 | D86: 48.737741
...

Sheet CF
A1: Status | B1: Entity | C1: Billing Date | D1: Due Date | E1: Payment Date/ Planned Date | F1: Currency | G1: Sub Total | H1: Tax | I1: Total Amount | J1: Amount (USD) | K1: Payee | L1: Invoice Number | M1: Description | N1: Account Code | O1: Account Category | P1: Department | Q1: Group | R1: Submitter | S1: Approval | T1: Authorisation | U1: Remarks | V1: GST Claimable
A2: Paid | B2: CN | C2: 46024 | D2: 46024 | E2: 46024 | F2: CNY | G2: 25 | H2: 0 | I2: 25 | J2: 3.596375 | K2: 招商银行 - 基本户 | M2: 网上企业银行-网上企业银行服务费 | N2: Bank Charges | O2: Bank Charges | P2: Finance | Q2: General & Administrative
A3: Paid | B3: CN | C3: 46024 | D3: 46024 | E3: 46024 | F3: CNY | G3: 4.38 | H3: 0 | I3: 4.38 | J3: 0.6300849 | K3: 招商银行 - 基本户 | M3: 网银支付-跨行-异地手续费 | N3: Bank Charges | O3: Bank Charges | P3: Finance | Q3: General & Administrative
A4: Paid | B4: CN | C4: 46024 | D4: 46024 | E4: 46024 | F4: CNY | G4: 2.67 | H4: 0 | I4: 2.67 | J4: 0.38409285 | K4: 招商银行 - 基本户 | M4: 网银支付-跨行-本地普通手续费 | N4: Bank Charges | O4: Bank Charges | P4: Finance | Q4: General & Administrative
A5: Paid | B5: CN | C5: 46031 | D5: 46031 | E5: 46031 | F5: CNY | G5: 10785 | H5: 0 | I5: 10785 | J5: 1551.4762 | K5: 福建省泉州宾馆有限责任公司 | L5: 09S137BF000004738176 | M5: 会务场地费 | N5: Accommodation - National | O5: Travelling Expenses | P5: General | Q5: General & Administrative
A6: Paid | B6: CN | C6: 46037 | D6: 46037 | E6: 46037 | F6: CNY | G6: 95.5 | H6: 0 | I6: 95.5 | J6: 13.738153 | K6: 报销 | L6: 报销12月 | M6: Total Courier Charges | N6: Courier Charges | O6: Courier Charges | P6: General | Q6: General & Administrative
A7: Paid | B7: CN | C7: 46037 | D7: 46037 | E7: 46037 | F7: CNY | G7: 4875 | H7: 0 | I7: 4875 | J7: 701.29313 | K7: 报销 | L7: 报销12月 | M7: Total General Expenses | N7: General Expenses | O7: General Expenses | P7: R&D - China | Q7: Research & Development
A8: Paid | B8: CN | C8: 46037 | D8: 46037 | E8: 46037 | F8: CNY | G8: 358 | H8: 0 | I8: 358 | J8: 51.50009 | K8: 报销 | L8: 报销12月 | M8: Total Insurance expenses | N8: Insurance expenses | O8: Employee Benefits | P8: HR | Q8: General & Administrative
A9: Paid | B9: CN | C9: 46037 | D9: 46037 | E9: 46037 | F9: CNY | G9: 906.15 | H9: 0 | I9: 906.15 | J9: 130.35421 | K9: 报销 | L9: 报销12月 | M9: Total Office Supplies | N9: Office Supplies | O9: Office Supplies | P9: General | Q9: General & Administrative
A10: Paid | B10: CN | C10: 46037 | D10: 46037 | E10: 46037 | F10: CNY | G10: 29 | H10: 0 | I10: 29 | J10: 4.171795 | K10: 报销 | L10: 报销12月 | M10: Total Office Supplies | N10: Office Supplies | O10: Office Supplies | P10: General | Q10: General & Administrative
A11: Paid | B11: CN | C11: 46037 | D11: 46037 | E11: 46037 | F11: CNY | G11: 3362.13 | H11: 0 | I11: 3362.13 | J11: 483.65921 | K11: 报销 | L11: 报销12月 | M11: Total Personal Meals - International | N11: Transportation fee - International | O11: Travelling Expenses | P11: Business Operation | Q11: Sales & Marketing
A12: Paid | B12: CN | C12: 46037 | D12: 46037 | E12: 46037 | F12: CNY | G12: 400 | H12: 0 | I12: 400 | J12: 57.542 | K12: 报销 | L12: 报销12月 | M12: Total Personal Meals - National | N12: Transportation fee - National | O12: Travelling Expenses | P12: R&D - China | Q12: Research & Development
A13: Paid | B13: CN | C13: 46037 | D13: 46037 | E13: 46037 | F13: CNY | G13: 0.01 | H13: 0 | I13: 0.01 | J13: 0.00143855 | K13: 报销 | L13: 报销12月 | M13: Total Rounding | N13: Bank Charges | O13: Bank Charges | P13: Finance | Q13: General & Administrative
A14: Paid | B14: CN | C14: 46037 | D14: 46037 | E14: 46037 | F14: CNY | G14: 2073.32 | H14: 0 | I14: 2073.32 | J14: 298.25745 | K14: 报销 | L14: 报销12月 | M14: Total Subscription Fee | N14: Subscription Fee | O14: Subscription Fee | P14: Finance | Q14: General & Administrative
A15: Paid | B15: CN | C15: 46037 | D15: 46037 | E15: 46037 | F15: CNY | G15: 66.89 | H15: 0 | I15: 66.89 | J15: 9.622461 | K15: 报销 | L15: 报销12月 | M15: Total Telecommunication | N15: Telecommunication | O15: Telecommunication | P15: Business Operation | Q15: Sales & Marketing
A16: Paid | B16: CN | C16: 46037 | D16: 46037 | E16: 46037 | F16: CNY | G16: 4292.8 | H16: 0 | I16: 4292.8 | J16: 617.54074 | K16: 报销 | L16: 报销12月 | M16: Total Transportation fee - International | N16: Transportation fee - International | O16: Travelling Expenses | P16: Business Operation | Q16: Sales & Marketing
... A19: Paid | B19: CN | C19: 46037 | D19: 46037 | E19: 46037 | F19: CNY | G19: 204 | H19: 0 | I19: 204 | J19: 29.34642 | K19: 报销 | L19: 报销12月 | M19: Total Transportation fee - National | N19: Transportation fee - National | O19: Travelling Expenses | P19: R&D - China | Q19: Research & Development
A20: Paid | B20: CN | C20: 46037 | D20: 46037 | E20: 46037 | F20: CNY | G20: 671.44 | H20: 0 | I20: 671.44 | J20: 96.590001 | K20: 上海融聚全才企业服务有限公司 | M20: 代理记账服务费-2026.01 | N20: Statutory Contribution | O20: Headcount Costs | P20: Finance | Q20: General & Administrative
A21: Paid | B21: CN | C21: 46037 | D21: 46037 | E21: 46037 | F21: CNY | G21: 426.88 | H21: 0 | I21: 426.88 | J21: 61.408822 | K21: 上海卓川人力资源有限公司 | M21: 人力资源服务费-成都，上海 | N21: Professional & Consultancy Fees | O21: Professional & Consultancy Fees | P21: HR | Q21: General & Administrative
A22: Paid | B22: CN | C22: 46037 | D22: 46037 | E22: 46037 | F22: CNY | G22: 246.53 | H22: 0 | I22: 246.53 | J22: 35.464573 | K22: 上海德必飞虹文化科技发展有限公司 | M22: 办公室电费 | N22: Electricity | O22: Utilities | P22: General | Q22: General & Administrative
A23: Paid | B23: CN | C23: 46037 | D23: 46037 | E23: 46037 | F23: CNY | G23: 277 | H23: 0 | I23: 277 | J23: 39.847835 | K23: 北京易点淘网络技术有限公司 | M23: 显示器租赁费-2025年12月 | N23: Leasing | O23: Non-Current Liabilities | P23: IT | Q23: General & Administrative
A24: Paid | B24: CN | C24: 46038 | D24: 46038 | E24: 46038 | F24: CNY | G24: 5503 | H24: 0 | I24: 5503 | J24: 791.63407 | K24: 北京芯普思信息技术有限公司 | L24: 09S137C5000002056994 | M24: 货款 | N24: R&D Contract Services | O24: R&D Contract Services | P24: R&D - China | Q24: Research & Development
A25: Paid | B25: CN | C25: 46045 | D25: 46045 | E25: 46045 | F25: CNY | G25: -569458.5 | H25: 0 | I25: -569458.5 | J25: -81919.453 | K25: 格创东智（深圳）科技有限公司 | L25: INV-0001 | M25: GT 001-202511-章鱼 | N25: Sales - Services Fees | O25: Revenue | P25: R&D - China | Q25: Research & Development
A26: Paid | B26: CN | C26: 46052 | D26: 46052 | E26: 46052 | F26: CNY | G26: -381.92 | H26: 0 | I26: -381.92 | J26: -54.941102 | K26: 招商银行 - 基本户 | M26: Interest Received | N26: Interest Income | O26: Other Income | P26: Finance | Q26: General & Administrative
A27: Paid | B27: CN | C27: 46053 | D27: 46053 | E27: 46053 | F27: CNY | J27: 1920.72 | K27: CN Staff | M27: Net Pay - January 2026 | N27: Salaries & Wages | O27: Headcount Costs | P27: Business Operation | Q27: =_xlfn.XLOOKUP(P27,[1]!Table2[Department],[1]!Table2[Group],"ERROR") -> Sales & Marketing
A28: Paid | B28: CN | C28: 46053 | D28: 46053 | E28: 46053 | F28: CNY | J28: 10359.73 | K28: CN Staff | M28: Net Pay - January 2026 | N28: Salaries & Wages | O28: Headcount Costs | P28: R&D - China | Q28: =_xlfn.XLOOKUP(P28,[1]!Table2[Department],[1]!Table2[Group],"ERROR") -> Research & Development
A29: Paid | B29: CN | C29: 46055 | D29: 46055 | E29: 46055 | F29: CNY | G29: 17.69 | H29: 0 | I29: 17.69 | J29: 2.54 | K29: 招商银行 - 基本户 | M29: 网银支付-跨行-异地手续费 | N29: Bank Charges | O29: Bank Charges | P29: Finance | Q29: General & Administrative
A30: Paid | B30: CN | C30: 46055 | D30: 46055 | E30: 46055 | F30: CNY | G30: 2.67 | H30: 0 | I30: 2.67 | J30: 0.38 | K30: 招商银行 - 基本户 | M30: 网银支付-跨行-本地普通手续费 | N30: Bank Charges | O30: Bank Charges | P30: Finance | Q30: General & Administrative
A31: Paid | B31: CN | C31: 46055 | D31: 46055 | E31: 46055 | F31: CNY | G31: 25 | H31: 0 | I31: 25 | J31: 3.6 | K31: 招商银行 - 基本户 | M31: 网上企业银行-网上企业银行服务费 | N31: Bank Charges | O31: Bank Charges | P31: Finance | Q31: General & Administrative
A32: Paid | B32: CN | C32: 46066 | D32: 46066 | E32: 46066 | F32: CNY | G32: 3029.4 | H32: 0 | I32: 3029.4 | J32: 435.79 | K32: 报销 | L32: 报销1月 | M32: Total Business Meals - International | N32: Staff Welfare - Meal & Refreshment | O32: Employee Benefits | P32: HR | Q32: General & Administrative
A33: Paid | B33: CN | C33: 46066 | D33: 46066 | E33: 46066 | F33: CNY | G33: 12 | H33: 0 | I33: 12 | J33: 1.73 | K33: 报销 | L33: 报销1月 | M33: Total Courier Charges | N33: Courier Charges | O33: Courier Charges | P33: General | Q33: General & Administrative
A34: Paid | B34: CN | C34: 46066 | D34: 46066 | E34: 46066 | F34: CNY | G34: 397.48 | H34: 0 | I34: 397.48 | J34: 57.18 | K34: 报销 | L34: 报销1月 | M34: Total Office Supplies | N34: Office Supplies | O34: Office Supplies | P34: General | Q34: General & Administrative
A35: Paid | B35: CN | C35: 46066 | D35: 46066 | E35: 46066 | F35: CNY | G35: 172.5 | H35: 0 | I35: 172.5 | J35: 24.81 | K35: 报销 | L35: 报销1月 | M35: Total Personal Meals - International | N35: Personal Meals - International | O35: Travelling Expenses | P35: HR | Q35: General & Administrative
A36: Paid | B36: CN | C36: 46066 | D36: 46066 | E36: 46066 | F36: CNY | G36: 350.19 | H36: 0 | I36: 350.19 | J36: 50.38 | K36: 报销 | L36: 报销1月 | M36: Total Staff Welfare - Gift & Tokens | N36: Staff Welfare - Gift & Tokens | O36: Employee Benefits | P36: HR | Q36: General & Administrative
A37: Paid | B37: CN | C37: 46066 | D37: 46066 | E37: 46066 | F37: CNY | G37: 600 | H37: 0 | I37: 600 | J37: 86.31 | K37: 报销 | L37: 报销1月 | M37: Total Staff Welfare - Gift & Tokens | N37: Staff Welfare - Gift & Tokens | O37: Employee Benefits | P37: HR | Q37: General & Administrative
A38: Paid | B38: CN | C38: 46066 | D38: 46066 | E38: 46066 | F38: CNY | G38: 656.77 | H38: 0 | I38: 656.77 | J38: 94.48 | K38: 报销 | L38: 报销1月 | M38: Total Subscription Fee | N38: Subscription Fee | O38: Subscription Fee | P38: Finance | Q38: General & Administrative
A39: Paid | B39: CN | C39: 46066 | D39: 46066 | E39: 46066 | F39: CNY | G39: 1610.42 | H39: 0 | I39: 1610.42 | J39: 231.67 | K39: 报销 | L39: 报销1月 | M39: Total Transportation fee - National | N39: Transportation fee - National | O39: Travelling Expenses | P39: General | Q39: General & Administrative
A40: Paid | B40: CN | C40: 46066 | D40: 46066 | E40: 46066 | F40: CNY | G40: 86.7 | H40: 0 | I40: 86.7 | J40: 12.47 | K40: 报销 | L40: 报销1月 | M40: Total Transportation fee - National | N40: Transportation fee - National | O40: Travelling Expenses | P40: General | Q40: General & Administrative
A41: Paid | B41: CN | C41: 46066 | D41: 46066 | E41: 46066 | F41: CNY | G41: 528.69 | H41: 0 | I41: 528.69 | J41: 76.05 | K41: 上海德必飞虹文化科技发展有限公司 | M41: 办公室电费 | N41: Electricity | O41: Utilities | P41: General | Q41: General & Administrative
A42: Paid | B42: CN | C42: 46066 | D42: 46066 | E42: 46066 | F42: CNY | G42: 426.88 | H42: 0 | I42: 426.88 | J42: 61.41 | K42: 上海卓川人力资源有限公司 | M42: 人力资源服务费-成都，上海 | N42: Professional & Consultancy Fees | O42: Professional & Consultancy Fees | P42: HR | Q42: General & Administrative
...

Sheet Receivable
A1: Alpha X Technology Pte Ltd (Singapore) | J1: SGD | K1: 0.77012503
A2: Status | B2: Entity | C2: Invoice Date | D2: Due Date | E2: Expected Inflow | F2: Payment Received Date | G2: Currency | H2: Sub Total | I2: Tax | J2: Total Amount | K2: Amount (USD) | L2: Client Name | M2: Invoice Number | N2: Description | O2: Project Code | Q2: Account Code | R2: Account Category | S2: Department | T2: SST | U2: Remarks
A3: Paid | B3: SG | C3: 46021 | D3: 46051 | E3: 46049 | F3: 46049 | G3: USD | H3: 8978 | I3: 808.02 | J3: =H3+I3 -> 9786.02 | K3: =IF(G3="SGD", J3*$K$1, J3) -> 9786.02 | L3: Soitec Microelectronics Singapore Pte Ltd | M3: INV 2512002 | N3: Development Support Services for PR1 Visual Inspect automation - December 2025 | O3: Soitec 001-202501- PR1 ADSS | P3: SG-00017-7 | Q3: Revenue | R3: Revenue | S3: Sales & Pre-sales | T3: Yes
A4: Paid | B4: SG | C4: 46043 | D4: 46073 | E4: 46108 | F4: 46108 | G4: SGD | H4: 8866.67 | I4: 798 | J4: =H4+I4 -> 9664.67 | K4: =IF(G4="SGD", J4*$K$1, J4) -> 7443.0043 | L4: VisionPower Semiconductor Manufacturing Company Pte Ltd | M4: INV 2601001 | N4: Power BI Consultant Fees - December 2025 | O4: VSMC 001-202508-Power BI | P4: SG-00010-1 | Q4: Revenue | R4: Revenue | S4: Sales & Pre-sales | T4: Yes
A5: Paid | B5: SG | C5: 46044 | D5: 46074 | E5: 46080 | F5: 46080 | G5: SGD | H5: 5000 | I5: 0 | J5: =H5+I5 -> 5000 | K5: =IF(G5="SGD", J5*$K$1, J5) -> 3850.6252 | L5: Armstrong Industrial Corporation Limited | M5: INV 2601002 | N5: AX JIT - IOT BOX (Tianjin) | O5: Armstrong 002-202509- AX JIT (AEM) | P5: SG-00031-1 | Q5: Revenue | R5: Revenue | S5: R&D - Team D | T5: No
A6: Paid | B6: SG | C6: 46052 | D6: 46082 | E6: 46080 | F6: 46080 | G6: SGD | H6: 26900 | I6: 2421 | J6: =H6+I6 -> 29321 | K6: =IF(G6="SGD", J6*$K$1, J6) -> 22580.836 | L6: Armstrong Industrial Corporation Limited | M6: INV 2601003 | N6: Implementation fees - CN Suzhou (Part 2) | O6: Armstrong 001-202508-MES | P6: SG-00008-Suzhou-2 | Q6: Revenue | R6: Revenue | S6: R&D - Team D | T6: Yes
A7: Paid | B7: SG | C7: 46056 | D7: 46086 | E7: 46142 | F7: 46140 | G7: SGD | H7: 8866.67 | I7: 798 | J7: =H7+I7 -> 9664.67 | K7: =IF(G7="SGD", J7*$K$1, J7) -> 7443.0043 | L7: VisionPower Semiconductor Manufacturing Company Pte Ltd | M7: INV 2602001 | N7: Power BI Consultant Fees - January 2026 | O7: VSMC 001-202508-Power BI | P7: SG-00010-2 | Q7: Revenue | R7: Revenue | S7: Sales & Pre-sales | T7: Yes
A8: Paid | B8: SG | C8: 46056 | D8: 46086 | E8: 46091 | F8: 46091 | G8: USD | H8: 8978 | I8: 808.02 | J8: =H8+I8 -> 9786.02 | K8: =IF(G8="SGD", J8*$K$1, J8) -> 9786.02 | L8: Soitec Microelectronics Singapore Pte Ltd | M8: INV 2602002 | N8: Development Support Services for PR1 Visual Inspect automation - January 2026 | O8: Soitec 001-202501- PR1 ADSS | P8: SG-00017-8 | Q8: Revenue | R8: Revenue | S8: Sales & Pre-sales | T8: Yes
A9: Paid | B9: SG | C9: 46062 | D9: 46092 | E9: 46142 | F9: 46125 | G9: SGD | H9: 26900 | I9: 2421 | J9: =H9+I9 -> 29321 | K9: =IF(G9="SGD", J9*$K$1, J9) -> 22580.836 | L9: Armstrong Industrial Corporation Limited | M9: INV 2602003 | N9: Implementation fees - CN Tianjin (UAT Completion) | O9: Armstrong 001-202508-MES | P9: SG-00008-Tianjin-5 | Q9: Revenue | R9: Revenue | S9: R&D - Team D | T9: Yes
A10: Paid | B10: SG | C10: 46063 | D10: 46093 | E10: 46142 | F10: 46125 | G10: SGD | H10: 2609.69 | I10: 234.87 | J10: =H10+I10 -> 2844.56 | K10: =IF(G10="SGD", J10*$K$1, J10) -> 2190.6669 | L10: Armstrong Industrial Corporation Limited | M10: INV 2602004 | N10: Consultation Fee : AOT 17th Nov to 21st Nov 2025 | O10: Armstrong 001-202508-MES | Q10: Revenue | R10: Revenue | S10: R&D - Team D | T10: Yes
A11: Paid | B11: SG | C11: 46080 | D11: 46110 | E11: 46142 | F11: 46125 | G11: SGD | H11: 1948.24 | I11: 175.34 | J11: =H11+I11 -> 2123.58 | K11: =IF(G11="SGD", J11*$K$1, J11) -> 1635.4221 | L11: Armstrong Industrial Corporation Limited | M11: INV 2602005 | N11: Consultation Fee: AOT and ATS 4th Jan - 16th Jan 2026 | O11: Armstrong 001-202508-MES | Q11: Revenue | R11: Revenue | S11: R&D - Team D | T11: Yes
A12: Paid | B12: SG | C12: 46084 | D12: 46114 | E12: 46142 | F12: 46154 | G12: SGD | H12: 585.13 | I12: 52.66 | J12: =H12+I12 -> 637.79 | K12: =IF(G12="SGD", J12*$K$1, J12) -> 491.17804 | L12: Armstrong Industrial Corporation Limited | M12: INV 2603001 | N12: Consultation Fee : ATS Go Live 2 Feb - 6 Feb 2026. | O12: Armstrong 001-202508-MES | Q12: Revenue | R12: Revenue | S12: R&D - Team D | T12: Yes
A13: Paid | B13: SG | C13: 46084 | D13: 46114 | E13: 46142 | F13: 46149 | G13: SGD | H13: 8866.67 | I13: 798 | J13: =H13+I13 -> 9664.67 | K13: =IF(G13="SGD", J13*$K$1, J13) -> 7443.0043 | L13: VisionPower Semiconductor Manufacturing Company Pte Ltd | M13: INV 2603002 | N13: Power BI Consultant Fees - February 2026 | O13: VSMC 001-202508-Power BI | P13: SG-00010-3 | Q13: Revenue | R13: Revenue | S13: Sales & Pre-sales | T13: Yes
A14: Paid | B14: SG | C14: 46086 | D14: 46116 | E14: 46107 | F14: 46107 | G14: USD | H14: 8978 | I14: 808.02 | J14: =H14+I14 -> 9786.02 | K14: =IF(G14="SGD", J14*$K$1, J14) -> 9786.02 | L14: Soitec Microelectronics Singapore Pte Ltd | M14: INV 2603003 | N14: Development Support Services for PR1 Visual Inspect automation - February 2025 | O14: Soitec 001-202501- PR1 ADSS | P14: SG-00017-9 | Q14: Revenue | R14: Revenue | S14: Sales & Pre-sales | T14: Yes
A15: Paid | B15: SG | C15: 46087 | D15: 46117 | E15: 46090 | F15: 46090 | G15: SGD | H15: 2099 | I15: 188.91 | J15: =H15+I15 -> 2287.91 | K15: =IF(G15="SGD", J15*$K$1, J15) -> 1761.9768 | L15: Infinix Hospitality Management Pte Ltd | M15: INV 2603004 | N15: AI Scheduler Setup Fee (Phase 1) + AI Scheduler Monthly Subscription | O15: Infinix 001-202603-AX trace | P15: SG-00045-1 | Q15: Revenue | R15: Revenue | S15: R&D - Team D | T15: Yes
A16: Paid | B16: SG | C16: 46093 | D16: 46123 | E16: 46142 | F16: 46154 | G16: SGD | H16: 46400 | I16: 4176 | J16: =H16+I16 -> 50576 | K16: =IF(G16="SGD", J16*$K$1, J16) -> 38949.844 | L16: Armstrong Industrial Corporation Limited | M16: INV 2603005 | N16: Implementation Fees – CN Changchun (Kick Off) | O16: Armstrong 001-202508-MES | P16: SG-00008-Changchun-7 | Q16: Revenue | R16: Revenue | S16: R&D - Team D | T16: Yes
A17: Paid | B17: SG | C17: 46094 | D17: 46124 | E17: 46107 | F17: 46107 | G17: USD | H17: 1000 | I17: 90 | J17: =H17+I17 -> 1090 | K17: =IF(G17="SGD", J17*$K$1, J17) -> 1090 | L17: Gtrontec Technology Pte Ltd | M17: INV 2603006 | N17: AX Trace Digital Marketing Solution 19 Feb 2026 – 18 Mar 2026 (1/6) | O17: GT 002-202602-AX Trace Digital Mktg Solution | P17: SG-00041-1 | R17: Revenue | S17: R&D - Team D | T17: Yes
A18: Paid | B18: SG | C18: 46111 | D18: 46141 | E18: 46173 | F18: 46139 | G18: USD | H18: 8978 | I18: 808.02 | J18: =H18+I18 -> 9786.02 | K18: =IF(G18="SGD", J18*$K$1, J18) -> 9786.02 | L18: Soitec Microelectronics Singapore Pte Ltd | M18: INV 2603007 | N18: Development Support Services for PR1 Visual Inspect automation - March 2026 | O18: Soitec 001-202501- PR1 ADSS | P18: SG-00017-10 | Q18: Revenue | R18: Revenue | S18: Sales & Pre-sales | T18: Yes
A19: Paid | B19: SG | C19: 46113 | D19: 46143 | E19: 46173 | F19: 46170 | G19: SGD | H19: 8866.67 | I19: 798 | J19: =H19+I19 -> 9664.67 | K19: =IF(G19="SGD", J19*$K$1, J19) -> 7443.0043 | L19: VisionPower Semiconductor Manufacturing Company Pte Ltd | M19: INV 2604001 | N19: Power BI Consultant Fees - March 2026 | O19: VSMC 001-202508-Power BI (1st)
